
### Promise

- 特点1

 `promise`代表一个异步操作，它有三种状态
 1、进行中`(pending)`
 2、已完成`(resolved/fullfilled)`
 3、已失败（rejected)

- 特点2

 `Promise`状态一旦改变，就不会再改变，`Promise`对象的状态改变，只有两种可能
 1、从pending变为resolved
 2、从pending变为rejected

### `Promise`的使用

- `Promise`是一个构造函数，我们可以通过 ==new== 关键字来创建一个peomise实例，也可以直接使用`Promise`的一些静态方法

1、new一个`Promise`示例

```
function fn(){
 return new Promise((resolve,rehect) => {
  setTimeout(()=>{
   let num = Math.ceil(Math.random()*10)
   if(num<5>){
    resolve(num)
   }else{
    reject('数字太大了')
   }
  },1000)
 })
}
```

2、Promise.prototype.then()
- then方法接收两个回调函数，onFullfilled和onRejected,两个参数都是可选的参数，一个是当Promise变成已完成状态（fullfilled)时调用的回调函数，另一个是当Promise变成接受状态或这时拒绝状态（rejected）时调用的函数。

 实例

 ```
 fn1().then((data)=>{
  console.log(data);  //返回的是resolved状态时的数据
 },(err)=>{
  console.log(err);   //返回的是rejected状态时的数据
 })
 ```

- 如果==then==方法中出现异常，则调用失败状态的方法（reject）跳转到下一个then的onRejected

 实例

 ```
 let p = new Promise((resolve,reject)=>{
	 resolve(1)
 })

 p.then(data=>2).then(
	 data=>{throw 'this is err'},
	 err=>{console.log('err1:'+err)})
	 .then(
		 data=>{console.log(data)},
		 err=>{console.log('err2:'+err)}
		)

	输出：err2:this is err
 ```

- 如果then方法没有传入任何回调，则继续向下传递（即所谓的值穿透）
 
 ```
 let p = new Promise((resolve,reject) => {
	 resolve(1)
 })
 p.then(data=>{return 2}).then().then().then(data=>{
	 console.log(data)  //2
 })
 ```
 
- 如果then方法中返回了一个Promise对象，那就以这个对象为准，返回它的结果

 ```
 let p = new Promise((resolve,reject) => {
	 resolve(1)
 })

 p.then(data =>{
	 return new Promise((resolve,reject) => {
		 resolve(2)
	 })
 }).then(data => {
	 console.log(data);   //2
 })
 ```

3、Promise.prototype.catch()
- ==catch==方法可以用于promise组合中的错误处理，此方法返回一个Promise,并且处理拒绝的情况
此方法捕获错误或失败比then的第二个参数看着就舒服一点。

实例

```
fn1().then(data=>{
	console.log(data);
}).catch(err=>{
	console.log(err);
})
```
- catch方法返回的是一个新的Promise对象，如果onRejected回调抛出一个错误或返回一个本身
失败的Promise,通过catch返回的Promise会被rejected,否则，
它就是一个成功的（resolved）promise实例

实例

```
fn1().catch(err => {
	console.log('err1:'+err)
	return err
}).then(data => {
	console.log('data：'+data)
}).catch(err => {
	console.log('err2:'+err)
})
输出：
err1:数字太大
data：数字太大
```

4、Promise.prortotype.finally()
- 在promise结束时，不管成功还是失败都将执行其onFinally回调，该回调无参数，适用于同样的语句在then()和catch()中各写一次的情况

```
p.finally(onFinally);

p.finally(function() {
  // 返回状态为(resolved 或 rejected)
});
```
5、Promise.resolve()
- 接收一个值，将现有对象转为Promise 对象

实例
```
const p = Promise.resolve(222);
Promise.resolve(p).then((value)=>{
	console.log(value); //222
})
```
6、Promise.reject()
- 返回一个带有拒绝原因的对象
实例
```
Promise.reject('失败的返回信息').then(data=>{
	console.log(data);
}).catch(err=>{
	console.log('err:'+err);
})

输出：//err:失败的返回信息
```
7、Promise.all()
- Promise.all(iterable)用于将多个Promise 实例包装成一个新的 Promise实例，参数为一组 Promise 实例组成的数组
- 当所有的Promise队列状态都是resolve的时候，才会返回一个新的状态为resolved的promise对象
实例
```
let p1 = Promise.resolve(1);
let p2 = Promise.resolve(2);
let p3 = Promise.resolve(3);

let p = Promise.all([p1,p2,p3]);

p.then(data=>{
	console.log(data);  //[1,2,3]
})
```
- 只要有一个实例 Rejected ，此时第一个被 Rejected 的实例返回值就会传递给 P 的回调函数

- **应用场景在我们有一个接口，需要其他两个或多个接口返回的数据作为参数时会多一些**
实例
```
let p1 = Promise.resolve(1)
let p2 = Promise.resolve(2)
let p3 = Promise.reject(3)

let p = Promise.all([p1, p2, p3])
p.then(data => {
  console.log(data)
}).catch(err => {
  console.log("err:" + err) // 3
})
```
8、Promise.race()
- race方法和和all方法相反，只要迭代对象中有一个状态改变了，它的状态就跟着改变，并将那个改变状态实例的返回值传递给回调函数。
实例
```
let p1 = Promise.resolve(1)
let p2 = Promise.resolve(2)
let p3 = Promise.reject(3)

Promise.race([p1, p2,p3])
  .then(value => {
    console.log(value) // 2
  })

输出：1
```
9、Promise.try()
- 不管函数fn是不是异步操作，都用then方法指定下一步流程，用catch方法处理fn抛出的错误

实例
则，如果函数fn是同步的，那么这波操作会把它转成异步，如下输出
```
let fn = () =>{
	console.log('fn');
}
Promise.resolve(fn).then(cb => cb())
console.log('hahahaha')

输出：hahahaha
		  fn
```
- 让同步函数同步执行，异步函数异步执行，并且让它们具有统一的api
```
const fn = () => console.log('fn);
(
	() => new Promise(resolve => {
		resolve(fn())
	})
)().then(()=>{
	console.log('222');
}).catch(err => {
	console.log(err)
})

console.log('111');

输出：fn
		111
		222
```

- 但是代码不优雅，我们用try的方法
```
const fn = () => console.log('fn');
Promise.try(fn).then(()=>{
	console.log(222)
}).catch(err=>{
	console.log(err)
})

console.log('111')

依次输出：fn 111 222
```
- onRejected和catch区别
	其实promise.then(onFullfilled,onRejected)在onFullfilled回调中发生异常的话，在onRejected中是捕获不到这个异常的，
	使用catch就可以捕获到前面onFullfilled的异常


	实例
	```
	Promise.reject(1).then(()=>{
		console.log("我是对的")
	}).then(null,err=>{
		console.log('err:':+err)
	})

	等价于

	Promise.reject(1).then(()=>{
		console.log('我是对的')
	}).catch(err=>{
		console.log('err:'+err)
	})
	```
10、then中抛错未处理

- 如果在then中抛错，而没有对错误进行处理(catch),那么会一直保持reject状态，直到catch了错误

实例

```
Promise.resolve().then(()=>{
	console.log(a)
}).then(()=>{
	console.log('task 2')
}).catch((err)=>{
	console.log('err:'+err)
}).then(()=>{
	console.log('last task')
})

输出：
err:ReferenceError: a is not defined
VM290:14 finaltask
```
- 输出结果先走了catch然后走了最后一个then，第一个then中抛出错误并跳过了第二个then
	也就是说如果我们没有处理这个错误(无catch)的话，就不会往下执行了
- Promise的缺点之一就是无法房promise中断，利用这个特性可以让Promise中断执行

11、异步回调中抛错catch捕捉不到

```
consot p = new Promise((resolve,reject)=>{
	throw new Error('这是异常抛出的一个错')
});
p.catch((error)=>{
	console.log('err:'+error)
})

输出：
err:Error:这是异常抛出的一个错
```
按照上述内容，在Promise对象的处理器函数中直接抛出错误，catch是可以捕捉到的

- 在Promise对象的处理器函数中模拟一个**异步抛错**
```
const p = new Promise((resolve,reject)=>{
	setTimeout(()=>{
		throw new Error('这是一个异常抛错信息')
	},0)
})
p.catch((error)=>{
	console.log(error)
})

报错：
VM458:2 Uncaught Error: 这是一个异常抛错信息
at <anonymous>:2:26
```
这种情况catch是捕捉不到的，因为JS 事件循环列表有宏任务与微任务之分，setTimeOut是宏任务， promise是微任务，执行顺序不同
- 那上述代码的执行顺序是：
	1、代码执行栈进入promise触发setTimeout,setTimeout回调函数进入宏任务队列
	2、代码执行promise的的catch方法，进入微任务队列，此时setTimeout回调还没有执行
	3、执行栈检查发现当前微任务队列执行完毕，开始执行宏任务队列
	4、执行 `throw new Error('这是一个异常抛错信息')`,此时这个异常其实是在Promise外部抛出的

- 解决
	使用`try catch`捕获异常主动触发`reject`

	```
	const p = new Promise((resolve,reject)=>{
		setTimeout(()=>{
			try{
				throw new Error('这是抛出的一个异常错误')
			}catch(e){
				reject(e)
			}
		})
	})
	p.catch((error)=>{
		console.log(error)
	})
	```
### 手写一个Promise-----加深对promise的理解
- 构造方法核心基础搭建
	我们现在已经知道promise的用法：
	1、Promise有三种状态：进行中(pending)、已完成(resolved/Fullfilled)、已失败（Rejected）
	2、Promise是一个构造方法，实例化Promise时传入一个函数作为处理器
		。处理器函数有两个参数（resolve和reject），分别将结果变为成功状态和失败状态
		。Promise对象执行成功了要有一个结果，通过resolve传递出去，失败的话可以将失败原因通过reject传递出入
	3、Promise的原型上定义着then方法

	**根据以上需求可以写出一个基础的结构**
	```
	function Promise(executor){
		//状态描述pending、resolved、rejected
		this.state = 'pending'
		//成功结果
		this.value = undefined
		//失败原因
		this.reason = undefined

		function resolve(value){}

		function reject(reason){}
	}

	Promise.prototype.then = function(onFullfilled,onRejected){}
	```
	**初始化实例executor立即执行，处理器函数（executor）是会立即执行的，所以我们更改代码**

	```
	function Promise(ececutor) {
		this.state = 'pending'
		this.value = undefined
		this.reason = undefined

		//让其处理器函数立即执行
		try{
			executor(resolve,reject)
		} catch(err){
			reject(err)
		}
		function resolve(value){}
		function reject(reason){}
	}
	```

	**resolve&reject回调实现**
	在Promise的规范中规定，当Promise对象已经由pending状态变为成功状态（resolved）或失败状态（rejected）后不可再次更改状态，也就是
	说成功或失败后状态不可再改变。

	因此我们更新状态时要判断，如果当前状态是pending，才可以更新，由此我们来完善`resolve`和`reject`方法
	```
	let _this = this;
	function resolve(value){
		if(_this.state === 'pending'){
			_this.value = value
			_this.state = "resolved"
		}
	}

	function reject(reason){
		if(_this.state === 'pending'){
			_this.reason = reason
			_this.state = "rejected
		}
	}
	```
	**then方法的基础实现**
	then方法有两个回调，当Promise状态发生改变，成功或失败会分别调用then方法的两个回调

	根据state来调用不同的回调函数
	```
	Promise.prototype.then = function(onFullfilled,onRejected) {
		if(this.state === 'resolved'){
			if(typeof onFullfilled === 'function'){
				onFullfilled(this.value)
			}
		}
		if(this.state === 'rejected') {
			if(typeof onRejected === 'fcuntion'){
				onRejected(this.reason)
			}
		}
	}
	```
	**让Promise支持异步**

	到了这里，我们来简单测试一下
	```
	let p = new Promise(resolve,reject) => {
		resolve(1)
	}
	p.then(data => {console.log(data)})   //1
	```
	符合预期

	再来试一下异步代码
	```
	let p = new Promise((resolve,reject) => {
		setTimeout(() => {
			resolve(1);
		},100)
	})
	p.then(data => {console.log(data)});   //无输出
	```
	setTimeout函数让resolve变成了异步执行，有延迟，调用then方法的时候，刺客状态还是等待（pending）状态，
	then方法即没有调用onFullfilled也没有调用onRejected

	此时我们可以参照发布订阅模式，再执行then方法时如果还在带等待状态（pending），就把回调函数临时寄存到队列，（就是一个数组里），
	当状态发生改变时依次从数组中取出执行就好了

	首先我们要在构造方法中新增两个Array类型的数组，用于存放成功和失败的回调函数
	```
	function Promise(executor) {
		let _this = this;
		this.state = 'pending';
		this.value = undefined;
		this.reason = undefined;
		//保存成功的回调函数
		this.onResolvedCallbacks = [];
		//保存失败的回调函数
		this.onRejectedCallbacks = [];
	}
	```
	我们还需要改善then方法，在then方法执行时如果状态还是等待，就将其回调函数存入对应数组
	```
	Promise.prototype.then = function(onFullfilled,onRejected) {
		//新增等待状态判断，此时异步代码还未走完，回调入数组队列
		if(this.state === 'pending'){
			if(typeof onFullfilled === 'function'){
				this.onResolvedCallbacks.push(onFullfilled)
			}
			if(typeof onRejected === 'function'){
				this.onRejectedCallbacks.push(onRejected)
			}
		}

		if(this.state === 'resolved'){
			if(typeof onFullfilled === 'function'){
				onFullfilled(thia.value)
			}
		}
		if(this.state === 'rejected'){
			if(typeof onRejected === 'function'){
				onRejected(this.reason)
			}
		}
	}
	```

	我们在resolve和reject方法中调用即可
	```
	function resolve(value){
		if(_this.state === 'pending'){
			_this.value = value;
			//遍历执行成功回调
			_this.onResolvedCallbacks.forEach(cb => cb(value))
			_this.state = 'resolved'
		}
	}

	function reject(reason){
		if(_this.state === 'pending'){
			_this.reason = reason;
			//遍历执行失败回调
			_this.onRejectedCallbacks.forEach(cb => cb(reason))
			_this.state = 'rejected'
		}
	}
	```

	到了这里，我们已经实现Promise的异步解决
	**实现Promise经典的链式调用**

	`Promise`的`then`方法可以链式调用，首先我们理解清楚`then`的需求是什么：

	- 首先`then`方法必须返回一个`promise`对象
	- 如果`then`方法中返回的是一个普通值（如Number，String等）就使用此值包装成一个新的`Promise`对象返回
	- 如果`then`方法中没有`return`语句，就返回一个用`undefined`包装的`Promise`对象
	- 如果`then`方法中出现异常，则调用失败状态的方法`（reject）`跳到下一个`then`的`onRejected`
	- 如果`then`方法没有传入任何回调，则继续向下传递（值穿透）
	- 如果`then`方法中返回了一个`Promise`对象，那就以这个对象为准，返回它的结果

> 上述就是需求，如果`then`中没有传入任何回调,则继续向下传递，但是每个`then`中又返回一个新的`Promise`，也就是说当`then`方法中没有回调时，我们需要将接受到的值继续向下传递，其实只要判断回调参数不为函数时，我们需要把他变成回调函数返回普通值即可

```
Promise.prototype.then = function(onFullfilled,onRejected) {
	onFullfilled = typeof onFullfilled === 'function' ? onFullfilled:value=>value
	onRejected = typeof onRejected === 'function' ? onRejected: err => {throw err}
	// ...
}
```
> 我们上面`then`实现中，在每个可执行处都加了参数是否为函数的类型校验，但是我们这里在`then`方法开头统一做了校验，就不需要参数校验了
现在的`then`方法变成了

```
Promise.prototype.then = function(onFullfilled,onRejected){
	onFullfilled = typeof onFullfilled === 'function' ? onFullfilled : value => value
	onRejected = typeof onRejected === 'function' ? onRejected : err => {throw err}
}
if(this.state === 'pending'){
	this.onResolvedCallbacks.push(onFullfilled)
	this.onRejectedCallbacks.push(onRejected)
}
if(this.state === 'resolved'){
	onFullfilled(this.value)
}
if(this.state === 'rejected'){
	this.onRejected(this.reason)
}
```
- 既然每个`then`都返回一个新的Promise，那么我们就先在`then`中创建一个Promise实例返回，开始改造
```
Promise.prototype.then = function(onFullfilled,onRejected){
	onFullfilled = typeof onFullfilled === 'function' ? onFullfilled : value => value
	onRejected = typeof onRejected === 'function' ? onRejected : err => {throw err}

	let Promise2 = new Promise((resolve,reject) => {
		if(this.state === 'pending'){
			this.onResolvedCallbacks.push(onFullfilled)
			this.onRejectedCallbacks.push(onRejected)
		}
		if(this.state === 'resolved'){
			onFullfilled(this.value)
		}
		if(this.state === 'rejected'){
			onRejected(this.reason)
		}
	})
	return promise2
}
```
- 接着在每个执行函数处使用`try..catch`语法，try中执行结果，catch中reject异常，原来的`then`方法中有resolved，rejected,pending三种逻辑判断，如下：
	- 在`resolved`状态判断时，`rejected`和`resolved`逻辑一致
	```
	if(this.state === 'resolved'){
		try {
			//拿到返回值resolve出去
			let x = onFullfilled(this.value)
			resolve(x)
		} catch(e) {
			//catch捕获异常reject抛出
			reject(e)
		}
	}
	```
`pending`状态判断，逻辑也和resolved相似，但是为了处理异步，我们在这里做了push操作。
```
if(this.state === 'pending'){
	this.onResolvedCallbacks.push(()=>{
		try {
			let x = onFullfilled(this.value)
			resolve(x)
		} catch(e) {
			reject(e)
		}
	})

	this.onRejectedCallbacks.push(()=> {
		try {
			let x = onRejected(this.reason)
			resolve(x)
		} catch(e) {
			reject(e)
		}
	})
}
```

- 解析then返回值与新Promise对象，
-	避免循环引用，当then的返回值与新生成的Promise对象为同一个（引用地址相同），则抛出typeError错误

	例：
	```
	let promise2 = p.then(data =>{
		return promise2;
	})

	//TypeError:Chaining cycle detected for promise #<pPromise>
	```

	如果返回了自己的Promise对象，状态永远为等待状态（pending)，再也无法成为resolved或时rejected,程序就死掉了，所以要先处理它
	```
	function resolvePromise(promise2,x,resolve,reject) {
		if(promise2 === x){
			reject(new TypeError('请避免Promise循环引用'))
		}
	}
	```

	- 判断x类型，分情况处理
	> 当x是一个Promise，就执行它，成功即成功，失败即失败，如果x是一个对象或是函数，再进一部处理它，否则就是一个普通值
	```
	function resolvePromise(promise2,x,resolve,reject) {
		if(promise2 === x){
			reject(new TypeErroe('请避免Promise重复引用'))
		}
	}

	if(x !== null &&(typeof x === 'object' || typeof x === 'function')){
		//可能是对象或者是函数
	} else {
		//是个普通值
		resolve(x)
	}
	```
	- 如果x是对象，尝试将对象上的`then`方法取出来，此时如果报错，那就将`promise2`转为失败态
	- 在这里`catch`防止报错是因为Promise有很多实现，假设另一个人实现的Promise对象使用`Object.defineProperty()`在取值时抛错，我们可以防止代码出现bug

	```
	//resolvePromise方法内部片段
	if(x !== null && (typeof x === 'object' || typeof x === 'function')){
		//可能是对象或是函数
		try {
			//尝试取出then方法引用
			let then = x.then
		} catch(e) {
			reject(e)
		}
	} else {
		//是个普通值
		resolve(x)
	}
	```
- 如果对象中有`then`,且`then`是函数类型，就可以认为是一个Promise对象，之后，使用x作为其this来调用执行`then`方法

```
// resolvePromise方法内部片段
if (x !== null && (typeof x === 'object' || typeof x === 'function')) {
  // 可能是个对象或是函数
  try {
    // 尝试取出then方法引用
    let then = x.then
    if (typeof then === 'function') {
      // then是function，那么执行Promise
      then.call(x, (y) => {
        resolve(y)
      }, (r) => {
        reject(r);
      })
    } else {
      resolve(x)
    }
  } catch (e) {
    reject(e)
  }
} else {
  // 是个普通值
  resolve(x)
}
```
- 此时我们还要考虑，如果`Promise`对象转为成功或是失败时传入的还是一个`Promise`对象，此时应该继续执行，直到最后的`Promise`执行完：
```
Promise.resolve(1).then(data => {
	return new Promise((resolve,reject)=>{
		//resolve传入的还是Promise
		resolve(new Promise((resolve,reject)=>{
			resolve(2)
		}))
	})
})
```
- 解决上述这种情况，我们可以采用递归，把调用`resolve`改写成递归执行`resolvePromise`,这样直到解析`Promise`成一个普通值才会终止
```
let called
if(x != null && (typeof x === 'object' || typeof x === 'function')){
	//可能是对象或是函数
	try {
		let then = x.then
		if(typeof then === 'function'){
			then.call(x,(y)=>{
				if(called) return
				called = true
				//递归调用，传入y若是Promise对象，继续循环
				resolvePromise(promise2,y,resolve,reject)
			},(r) => {
				reject(r)
			})
		}else{
			resolve(x)
		}
	} catch(e) {
		reject(e)
	}
}else{
	//普通值结束递归
	resolve(x)
}
```
- `Promise`中处理器函数是同步执行，而`then`方法是异步，我们在`then`方法内执行处的所有地方使用setTimeout变为异步即可。
```
setTimeout(()=>{
	try {
		let x = onFullfilled(value);
		resolvePromise(promise2,x,resolve,reject)
	} catch(e) {
		reject(e);
	}
},0)
```
> 现在`then`方法的完整代码是
```
```

### Generator

- 迭代器（Iterator）
1、iterator语法，简介
> 迭代器是一种接口，也可以说是一种规范
- js中不同的数据类型（如Array,Object,Set)等等，遍历的方式各不通，比如对象比哪里我们使用`for...in...`,数组用`for(),for...of,for...in..,forEach`等等，那么又没有统一的方式遍历呢，这就是迭代器存在的意义。它可以提供统一的遍历数据的方式：
- iterator语法
```
const obj = {
	[Symbol.iteratot]:function(){}
}
```
- `[Symbol.iterator]`属性名是固定的写法，只要拥有了该属性的对象，就能够用迭代器的方式进行遍历
- 迭代器的遍历方法是首先获得一个迭代器的指针，初始时该指针指向第一条数据之前
- 接着通过调用`next()`方法，改变指针的指向，让其指向下一条数据
- 每一次的`next`都会返回一个对象，该对象有两个属性
	。value代表想要获取的数据
	。done布尔值，false表示当前指针指向的数据有值，true表示遍历已经结束

2、iterator详解
- 在js中，Array/Set/Map/String都默认支持迭代器，由于数据和集合都支持迭代器，所以他们都可以用同一种方式来遍历，es6提供的`for-of`实际上就是使用迭代器来进行遍历，也就是说支持了迭代器的数据结构才能使用`for-of`循环
- 数组中使用迭代器遍历：
	```
	let arr = [{num:1},2,3]
	let it = arr[Symbol.iterator]()  //获取数组中的迭代器
	console.log(it.next()) //{value:Object {num:1},done:false}
	console.log(it.next())  //{value:2,done:false}
	console.log(it.next())  //{value:3,done:false}
	console.log(it.next())  //{value:undefined,done:true}
	```
- 集合中使用迭代器遍历
```
let list = new Set([1,3])
let it = list.entries()    //获取set集合中自带的迭代器
console.log(it.next()) //{value:[1,1],done:false}
console.log(it.next()) //{value:[3,3],done:false}
console.log(it.next()) //{value:undeined,done:true}
```
。集合与数组不同的是，我们可以使用`Set`中的`entries`方法获取迭代器
- 自定义对象中我们使用迭代器
。自定义对象没有迭代器属性，所以不支持迭代器迭代，我们知道`for..of`是无法遍历对象，因为`for..of`是使用迭代器迭代，所以对象不能用`for..of`
。因为自定义对象没有迭代器属性，那么我们可以为它加上`Symbol.iterator`这样的一个属性，并为它实现一个迭代器的方法，如下：
```
let obj = {
	name:'xxx',
	age:18,
	sex:'女',
	intro:function(){
		console.log('my name is '+this.name)
	},
	[Symbol.iterator]:function() {
		let i = 0;
		//获取当前对象的所有属性并生成一个数组
		let keys = Object.keys(this);
		return {
			next:function(){
				return {
					value:keys[i++],
					done:i>keys.length   //如果数组的数据已经遍历完就返回true
				}
			}
		}
	}
}

for(let attr of obj){
	console.log(attr)
}
//name
//age
//sex
//intro
```
3、iterator作用
	。 为各种数据结构，提供一个统一的、简便的访问接口
	。 使得数据结构的成员能够按某种次序排列
	。 es6创造了一种新的遍历命令`for..of`循环，iterator接口主要提供`for..of`消费
- 初识Generator
	。generator是一个函数，只不过是一个特殊的函数，普通的函数，你运行了这个函数，函数内部不会停，直到这个函数结束，而`generator`函数的特殊之处就是，中间可以停
1、 Generator函数的特点
```
function *generatorFun() {
	console.log('a');
	yield '1';
	console.log('b');
	yield '2';
	console.log('c');
	return '3';
}

let it = generatorFun()
it.next()
it.next()
it.next()
it.next()

输出：
a
b
c
{value: undefined, done: true}
```
- 不同于普通函数，Generator函数在`function`后面，函数名之前有个`*`
	。`*`用来表示函数为Generator函数
	。写法很多，`function* fn()`、`function*fn()`、`function *fn()`都可以
- 函数内部有yield字段
	。`yield`用来定义函数内部的状态，并让出执行权
	。这个关键字只出现在生成器函数体内，但是生成器中也可以没有yield关键字，函数遇到`yield`关键字的时候回暂停，并把`yield`后面的表达式结果抛出去
- 调用后其函数返回值使用了`next`方法
	。调用generator函数和调用普通函数一样，在函数后面加上()即可
	。generator函数不会像普通函数一样立即执行，而是返回一个指向内部状态对象的指针
	。所以调用迭代器对象iterator的next方法，指针就会从函数头部或者上一次停下来的地方开始执行
	。next方法其实就是将代码的控制权交还给生成器函数
2、分析执行过程
	```
	let it = generatorFun()
	1》it.next()
	//a
	//{value:'1',done:false}
	2》it.next()
	//b
	//{value:'2',done:false}
	3》it.next()
	//c
	//{value:'3',done:true}
	4》it.next()
	//{value:undefined,done:true}
	```
	。首先，generator函数执行，返回了一个指向内部状态对象的指针，定义的`it`
	。第一次调用`next`方法，从`generator`函数的头部开始执行，先是打印了a,执行到`yield`就停下了，并将`yield`后面的表达式值‘1’，作为返回对象的value属性值，此时函数还没有执行完，返回对象的done属性值是false
	。第二次调用`next`方法，从`generator`函数的上次执行停下的地方开始执行，执行到`yield`就停下了，并将`yield`后面的表达式‘2’，作为返回对象的value属相值，此时函数还没有执行完，返回对象的done属相值是false
	。第三次调用`next`方法，函数继续从上次执行停下的地方开始执行，此时函数已经结束，所以done属性值为true
	。第四次调用`next`方法，此时函数已经执行完了，所以返回对象的value值是undefined，done属性值是true.
	。如果在执行第三步的时候，如果没有return语句的话，就直接返回`{value:undefined,done:true}`
	generator函数yield放到那里它就通到那里，调用时使用next,调用一次走一步。
3、next参数传递
	。yield是有返回值的，next方法直接调用不传入参数的时候，yield表达式的返回值是undefined
	。当next传入参数的时候，该参数会作为上一步yield的返回值
	```
	function *yieldFn(){
		let a = yield '1'

		console.log(a)
		let b = yield '2'

		console.log(b)
		let c = yield '3'

		console.log(c)
		return 4
	}

	let it yieldFn()
	it.next()
	//{value:1,done:false}

	it.next()
	//undefined  //未传值，所以a为undefined
	//{value:2,done:false}

	it.next('hahaha')
	//hahaha
	//{value:3,done:false}

	it.next('xixixi')
	//xixixi
	//{value:4,done:true}
	```
4、理解yield
```
function *yieldFn(){
	console.log('start')
	let a = yield console.log('1')
	console.log(a)
	let b = yield console.log('2')
	console.log(b)
	return console.log('3')
}

let it = yieldFn()
1》it.next()
//start
//1
//{value:undefined,done:false}
2》it.next('我是a')
//我是a
//2
//{value:undefined,done:false}
3》it.next('我是b')
//我是b
//3
//{value:undefined,done:true}
```
- for..of遍历Generator
。它可以自动遍历Generator函数，而且此时不再需要调用next方法，一旦next方法返回对象的done属性为true,for..of循环就会终止，且不包含该返回对象
```
function *foo(){
	yield 1
	yield 2
	yield 3
	yield 4
	yield 5
	return 6
}

for(let i of foo()){
	console.log(i)
}
//1 2 3 4 5
```
- yield表达式
。在`yield`后面加上*号，表明它返回的是一个遍历器，这就被成为`yield*`表达式
```
function *foo(){
	yield 'foo1'
	yield 'foo2'
}
function *bar(){
	yield 'bar1'
	yield* foo()
	yield 'bar2'
}

for(let i of bar()){
	console.log(i)
}
//bar1 foo1 foo2 bar2
```
。`yield`后面如果不加*号，返回的是整个数组，加了*号就表示返回的是数组的遍历器
```
function *gen1(){
	yield ['a','b','c','d']
}
for(let i of gen1()){
	console.log(i)
}

//[a,b,c,d]
______________
function *gen2(){
	yield* ['a','b','c','d']
}
for(let i of gen2()){
	console.log(i)
}
//a b c d
```
- Generator中的return
。generator方法返回给定值，并结束遍历Generator函数
。当return无值时，就返回undefined
```
function *foo(){
	yield 1
	yield 2
	yield 3
}
var f = foo()
f.next()
//{value:1,done:false}

f.return('hahaha')
//由于调用了return方法，所以遍历已结束，done变true
//{value:'hahaha',done:true}

f.next()
//{value:undefined,done:true}
```
- Generator错误处理throw
。throw方法可以在Generator函数体外面抛出异常，在函数体内捕获。
```
function *foo(){
	try{
		yield 'hahaha'
	}catch(err){
		console.log('inside error:'+err)
	}
}
var it = foo()
try{
	it.throw('this is err')
}catch(err){
	console.log('out error:'+err)
}

//输出：out error：this is err
```

```
function *foo(){
  try{
    yield a
  }catch(err){
    console.log('inside error: ' + err)
  }
}
var it3 = foo()
it3.next()

输出：inside error: ReferenceError: a is not defined
{value: undefined, done: true}
```
。throw方法会附带执行下一个yield
```
var foo = function *foo(){
	try {
		yield 1
		yield 2
	} catch(e) {
		console.log('inside err')
	}
	yield 3
	yield 4

var it = foo()
it.next()
//1
//{value:1,done:false}
it.throw()
//inside err
//3
//{value: undefined, done: false}
it.next()
//4
//{value:undefined,done:false}
```
。执行throw,内部捕获到，输出`inside err`,此时`try{}catch(){}`代码块已经执行了catch，try{}catch(){}代码块已经结束，所以会继续向下走，执行yield继续向下找，所以再输出3，最后执行next方法，输出4、{value:undeined,done:false}。
- Generator与协程
。js的运行机制是单线程的，es6中的generator的实现，类似于开了多线程，但是依旧同时只能进行一个线程，不过可以切换。
。就像汽车在公路上行驶，js就像单行道（主线程）,但是有很多车道（辅助线程）都可以汇入车流（异步任务完成后回调进入主线程的任务队列）
。而Generator把js公路变成了多车道（协程实现），但是同一时间只有一个车道上的车能开（所以依然是单线程），不过可以自由变道（移交控制权）

- Generator之Thunk函数
。`thunk`函数的诞生源于一个编译器设计的问题：`求值策略`,即函数的参数到底应该何时求值
```
var x = 1;
function fn(n) {
	return n*10
}
fn(x + 5)
```
.如上所示，其中fn方法调用时`x+5`这个表达式应该什么时候求值，有两种思路
。**传值调用（call by value)**,先计算`x+5`的值，再奖6传入函数fn，这种做法会造成性能损失，比如，参数是一个表达式，但函数体内没有用到这个参数，那么先计算出值就会损耗性能且毫无意义。
。**传名调用（call by name)**,即直接将表达式`x+5`传入函数体，只在用到它的时候求值。
。先将参数放到一个临时函数之中，再将这个临时函数传入函数体。
```
function fn(m){
	return m * 2
}
fn(x+5)

//thunk实现思路
var thunk = function(){
	return x+5
}
function fn(thunk){
	return thunk()*2
}
```
- 基于Thunk函数的Generator自动执行器
```
function run(fn) {
	let gen = fn()
	function next(err,data) {
		//将指针移动到generator函数的下一步
		let result = gen.next(data)
		//判断是否结束
		if(result.done) return
		//递归，把next放进.value中
		result.value(next)
	}
	next()
}

//模拟异步方法
let sleep = function(n,callback) {
	setTimeout(()=>{
		console.log(n)
		callback && callback(n)
	},n)
}

//模拟异步方法进行thunk转换
let sleepThunk = Thunk(sleep)

//generator函数
let gen = function*(){
	let f1 = yield sleepThunk(1000)
	let f2 = yield sleepThunk(1500)
	..
	let fn = yield sleepThunk(2000)
}

//调用generator函数自动执行器
run(gen)
```
。上面代码的run函数，就是一个generator函数的自动执行器，内部的next函数就是thunk的回调函数
。next函数先将指针移到generator函数的下一步（gen.next方法）
。然后判断generator函数是否结束（result.done属性）
。如果没结束，就将next函数再传入thunk函数（result.value属性），否则就直接退出

### Generator优/缺 
- 优点
。优雅的流程控制方式，可以让函数可中断执行，在某些特殊需求还是很实用
。使用react-dva的可能会更有感触
。之前node的koa框架也用generator,不过后来被async/await替代了
- 缺点
generator函数执行必须靠执行器，所以才有了co函数库，（不了解co的可自行去了解一下），但是co模块约定，yield命令后面只能是thunk函数或Promise对象，只针对异步处理来说，还是不太方便